Workbook

Sheet Original
A1: STUDENTS
A2: Student ID | B2: Student Name | C2: Gender | D2: Age | E2: City | F2: Department | G2: Admission Year
A3: 1 | B3: Arjun | C3: M | D3: 20 | E3: Bangalore | F3: Computer Science | G3: 2022
A4: 2 | B4: Meera | C4: F | D4: 21 | E4: Mumbai | F4: Computer Science | G4: 2021
A5: 3 | B5: Ravi | C5: M | D5: 22 | E5: Hyderabad | F5: Mechanical | G5: 2021
A6: 4 | B6: Sneha | C6: F | D6: 20 | E6: Chennai | F6: Electrical | G6: 2022
A7: 5 | B7: Vikram | C7: M | D7: 23 | E7: Pune | F7: Mechanical | G7: 2020
A8: 6 | B8: Priya | C8: F | D8: 21 | E8: Bangalore | F8: Computer Science | G8: 2022
A9: 7 | B9: Rohit | C9: M | D9: 22 | E9: Delhi | F9: Electrical | G9: 2021
A10: 8 | B10: Neha | C10: F | D10: 20 | E10: Mumbai | F10: Civil | G10: 2023
A11: 9 | B11: Kiran | C11: M | D11: 24 | E11: Hyderabad | F11: Civil | G11: 2020
A12: 10 | B12: Anjali | C12: F | D12: 21 | E12: Chennai | F12: Computer Science | G12: 2021
A14: COURSES
A15: Course ID | B15: Course Name | C15: Department | D15: Instructor ID | E15: Credits
A16: 1 | B16: Data Structures | C16: Computer Science | D16: 1 | E16: 4
A17: 2 | B17: Machine Learning | C17: Computer Science | D17: 5 | E17: 4
A18: 3 | B18: Thermodynamics | C18: Mechanical | D18: 3 | E18: 3
A19: 4 | B19: Circuit Analysis | C19: Electrical | D19: 2 | E19: 3
A20: 5 | B20: Structural Design | C20: Civil | D20: 4 | E20: 3
A21: 6 | B21: Database Systems | C21: Computer Science | D21: 1 | E21: 4
A23: ENROLLMENTS
A24: Enrollment ID | B24: Student ID | C24: Course ID | D24: Semester | E24: Year
A25: 1 | B25: 1 | C25: 1 | D25: Fall | E25: 2023
A26: 2 | B26: 1 | C26: 2 | D26: Fall | E26: 2023
A27: 3 | B27: 2 | C27: 1 | D27: Spring | E27: 2023
A28: 4 | B28: 3 | C28: 3 | D28: Fall | E28: 2023
A29: 5 | B29: 4 | C29: 4 | D29: Fall | E29: 2023
A30: 6 | B30: 5 | C30: 3 | D30: Spring | E30: 2023
A31: 7 | B31: 6 | C31: 2 | D31: Fall | E31: 2023
A32: 8 | B32: 7 | C32: 4 | D32: Spring | E32: 2023
A33: 9 | B33: 8 | C33: 5 | D33: Fall | E33: 2023
A34: 10 | B34: 9 | C34: 5 | D34: Spring | E34: 2023
A35: 11 | B35: 10 | C35: 6 | D35: Fall | E35: 2023
A37: EXAMS
A38: Exam ID | B38: Student ID | C38: Course ID | D38: Score | E38: Grade
A39: 1 | B39: 1 | C39: 1 | D39: 88 | E39: A
A40: 2 | B40: 1 | C40: 2 | D40: 91 | E40: A
A41: 3 | B41: 2 | C41: 1 | D41: 76 | E41: B
A42: 4 | B42: 3 | C42: 3 | D42: 69 | E42: C
A43: 5 | B43: 4 | C43: 4 | D43: 82 | E43: B
...

Sheet Attendance
A1: ATTENDANCE
A2: Attendance ID | B2: Student ID | C2: Course ID | D2: Attendance Date | E2: Status
A3: 1 | B3: 1 | C3: 1 | D3: 46143 | E3: present
A4: 2 | B4: 1 | C4: 2 | D4: 46143 | E4: present
A5: 3 | B5: 2 | C5: 1 | D5: 46143 | E5: absent
A6: 4 | B6: 3 | C6: 3 | D6: 46144 | E6: present
A7: 5 | B7: 4 | C7: 4 | D7: 46144 | E7: present
A8: 6 | B8: 5 | C8: 3 | D8: 46144 | E8: excused

Sheet Students
A1: STUDENTS
A2: Student ID | B2: Student Name | C2: Gender | D2: Age | E2: City | F2: Department | G2: Admission Year
A3: 1 | B3: Arjun | C3: M | D3: 20 | E3: Bangalore | F3: Computer Science | G3: 2022
A4: 2 | B4: Meera | C4: F | D4: 21 | E4: Mumbai | F4: Computer Science | G4: 2021
A5: 3 | B5: Ravi | C5: M | D5: 22 | E5: Hyderabad | F5: Mechanical | G5: 2021
A6: 4 | B6: Sneha | C6: F | D6: 20 | E6: Chennai | F6: Electrical | G6: 2022
A7: 5 | B7: Vikram | C7: M | D7: 23 | E7: Pune | F7: Mechanical | G7: 2020
A8: 6 | B8: Priya | C8: F | D8: 21 | E8: Bangalore | F8: Computer Science | G8: 2022
A9: 7 | B9: Rohit | C9: M | D9: 22 | E9: Delhi | F9: Electrical | G9: 2021
A10: 8 | B10: Neha | C10: F | D10: 20 | E10: Mumbai | F10: Civil | G10: 2023
A11: 9 | B11: Kiran | C11: M | D11: 24 | E11: Hyderabad | F11: Civil | G11: 2020
A12: 10 | B12: Anjali | C12: F | D12: 21 | E12: Chennai | F12: Computer Science | G12: 2021

Sheet Courses
A1: COURSES
A2: Course ID | B2: Course Name | C2: Department | D2: Instructor ID | E2: Credits
A3: 1 | B3: Data Structures | C3: Computer Science | D3: 1 | E3: 4
A4: 2 | B4: Machine Learning | C4: Computer Science | D4: 5 | E4: 4
A5: 3 | B5: Thermodynamics | C5: Mechanical | D5: 3 | E5: 3
A6: 4 | B6: Circuit Analysis | C6: Electrical | D6: 2 | E6: 3
A7: 5 | B7: Structural Design | C7: Civil | D7: 4 | E7: 3
A8: 6 | B8: Database Systems | C8: Computer Science | D8: 1 | E8: 4

Sheet Enrollments
A1: ENROLLMENTS
A2: Enrollment ID | B2: Student ID | C2: Course ID | D2: Semester | E2: Year
A3: 1 | B3: 1 | C3: 1 | D3: Fall | E3: 2023
A4: 2 | B4: 1 | C4: 2 | D4: Fall | E4: 2023
A5: 3 | B5: 2 | C5: 1 | D5: Spring | E5: 2023
A6: 4 | B6: 3 | C6: 3 | D6: Fall | E6: 2023
A7: 5 | B7: 4 | C7: 4 | D7: Fall | E7: 2023
A8: 6 | B8: 5 | C8: 3 | D8: Spring | E8: 2023
A9: 7 | B9: 6 | C9: 2 | D9: Fall | E9: 2023
A10: 8 | B10: 7 | C10: 4 | D10: Spring | E10: 2023
A11: 9 | B11: 8 | C11: 5 | D11: Fall | E11: 2023
A12: 10 | B12: 9 | C12: 5 | D12: Spring | E12: 2023
A13: 11 | B13: 10 | C13: 6 | D13: Fall | E13: 2023

Sheet Exams
A1: EXAMS
A2: Exam ID | B2: Student ID | C2: Course ID | D2: Score | E2: Grade
A3: 1 | B3: 1 | C3: 1 | D3: 88 | E3: A
A4: 2 | B4: 1 | C4: 2 | D4: 91 | E4: A
A5: 3 | B5: 2 | C5: 1 | D5: 76 | E5: B
A6: 4 | B6: 3 | C6: 3 | D6: 69 | E6: C
A7: 5 | B7: 4 | C7: 4 | D7: 82 | E7: B
A8: 6 | B8: 5 | C8: 3 | D8: 73 | E8: B
A9: 7 | B9: 6 | C9: 2 | D9: 95 | E9: A
A10: 8 | B10: 7 | C10: 4 | D10: 67 | E10: C
A11: 9 | B11: 8 | C11: 5 | D11: 79 | E11: B
A12: 10 | B12: 9 | C12: 5 | D12: 85 | E12: A
A13: 11 | B13: 10 | C13: 6 | D13: 90 | E13: A

Sheet Instructors
A1: INSTRUCTORS
A2: Instructor ID | B2: Instructor Name | C2: Department | D2: Experience Years | E2: Salary
A3: 1 | B3: Dr Sharma | C3: Computer Science | D3: 15 | E3: 120000
A4: 2 | B4: Dr Iyer | C4: Electrical | D4: 12 | E4: 110000
A5: 3 | B5: Dr Gupta | C5: Mechanical | D5: 10 | E5: 100000
A6: 4 | B6: Dr Nair | C6: Civil | D6: 8 | E6: 90000
A7: 5 | B7: Dr Kapoor | C7: Computer Science | D7: 20 | E7: 150000

Sheet Payments
A1: PAYMENT S
A2: Payment ID | B2: Student ID | C2: Amount Paid | D2: Payment Date | E2: Payment Method
A3: 1 | B3: 1 | C3: 15000 | D3: 46122 | E3: HDFC Debit Card
A4: 2 | B4: 2 | C4: 15000 | D4: 46123 | E4: UPI
A5: 3 | B5: 3 | C5: 12000 | D5: 46124 | E5: Cash
A6: 4 | B6: 4 | C6: 15000 | D6: 46127 | E6: Credit Card

Sheet Analysis Data
F1: Student ID | G1: Student Name | H1: Course ID | I1: Course Name | J1: Department | K1: Score | L1: Grade | M1: Attendance Status | N1: Amount Paid
A2: Average Age of Students | B2: =AVERAGE(Table2[[#All],[Age]]) -> 21.4 | F2: =_xlfn.XLOOKUP(Original!B39,Table3[Student ID],Table3[Student ID]) -> 1 | G2: =_xlfn.XLOOKUP(Original!B3,Table2[Student Name],Table2[Student Name]) -> Arjun | H2: =_xlfn.XLOOKUP(Original!C39,Table3[Course ID],Table3[Course ID]) -> 1 | I2: =_xlfn.XLOOKUP(Table1[[#This Row],[Course ID]],Table4[Course ID],Table4[[Course Name ]]) -> Data Structures | J2: =_xlfn.XLOOKUP(Table1[[#This Row],[Course ID]],Table4[Course ID],Table4[Department]) -> Computer Science | K2: =_xlfn.XLOOKUP(Original!D39,Table3[Score],Table3[Score]) -> 88 | L2: =_xlfn.XLOOKUP(Original!E39,Table3[Grade],Table3[Grade]) -> A | M2: {=_xlfn.XLOOKUP(Table1[[#This Row],[Student ID]]&Table1[[#This Row],[Course ID]],Table9[Student ID]&Table9[Course ID],Table9[Status],"No Record")} -> present | N2: =_xlfn.XLOOKUP(Table1[[#This Row],[Student ID]],Table7[Student ID],Table7[Amount Paid],0) -> 15000
A3: Average Score Overall | B3: =AVERAGE(Table3[[#All],[Score]]) -> 81.363636 | F3: =_xlfn.XLOOKUP(Original!B40,Table3[Student ID],Table3[Student ID]) -> 1 | G3: =_xlfn.XLOOKUP(Original!B3,Table2[Student Name],Table2[Student Name]) -> Arjun | H3: =_xlfn.XLOOKUP(Original!C40,Table3[Course ID],Table3[Course ID]) -> 2 | I3: =_xlfn.XLOOKUP(Table1[[#This Row],[Course ID]],Table4[Course ID],Table4[[Course Name ]]) -> Machine Learning | J3: =_xlfn.XLOOKUP(Table1[[#This Row],[Course ID]],Table4[Course ID],Table4[Department]) -> Computer Science | K3: =_xlfn.XLOOKUP(Original!D40,Table3[Score],Table3[Score]) -> 91 | L3: =_xlfn.XLOOKUP(Original!E40,Table3[Grade],Table3[Grade]) -> A | M3: {=_xlfn.XLOOKUP(Table1[[#This Row],[Student ID]]&Table1[[#This Row],[Course ID]],Table9[Student ID]&Table9[Course ID],Table9[Status],"No Record")} -> present | N3: =_xlfn.XLOOKUP(Table1[[#This Row],[Student ID]],Table7[Student ID],Table7[Amount Paid],0) -> 15000
F4: =_xlfn.XLOOKUP(Original!B41,Table3[Student ID],Table3[Student ID]) -> 2 | G4: =_xlfn.XLOOKUP(Original!B4,Table2[Student Name],Table2[Student Name]) -> Meera | H4: =_xlfn.XLOOKUP(Original!C41,Table3[Course ID],Table3[Course ID]) -> 1 | I4: =_xlfn.XLOOKUP(Table1[[#This Row],[Course ID]],Table4[Course ID],Table4[[Course Name ]]) -> Data Structures | J4: =_xlfn.XLOOKUP(Table1[[#This Row],[Course ID]],Table4[Course ID],Table4[Department]) -> Computer Science | K4: =_xlfn.XLOOKUP(Original!D41,Table3[Score],Table3[Score]) -> 76 | L4: =_xlfn.XLOOKUP(Original!E41,Table3[Grade],Table3[Grade]) -> B | M4: {=_xlfn.XLOOKUP(Table1[[#This Row],[Student ID]]&Table1[[#This Row],[Course ID]],Table9[Student ID]&Table9[Course ID],Table9[Status],"No Record")} -> absent | N4: =_xlfn.XLOOKUP(Table1[[#This Row],[Student ID]],Table7[Student ID],Table7[Amount Paid],0) -> 15000
A5: Average Score By Department | F5: =_xlfn.XLOOKUP(Original!B42,Table3[Student ID],Table3[Student ID]) -> 3 | G5: =_xlfn.XLOOKUP(Original!B5,Table2[Student Name],Table2[Student Name]) -> Ravi | H5: =_xlfn.XLOOKUP(Original!C42,Table3[Course ID],Table3[Course ID]) -> 3 | I5: =_xlfn.XLOOKUP(Table1[[#This Row],[Course ID]],Table4[Course ID],Table4[[Course Name ]]) -> Thermodynamics | J5: =_xlfn.XLOOKUP(Table1[[#This Row],[Course ID]],Table4[Course ID],Table4[Department]) -> Mechanical | K5: =_xlfn.XLOOKUP(Original!D42,Table3[Score],Table3[Score]) -> 69 | L5: =_xlfn.XLOOKUP(Original!E42,Table3[Grade],Table3[Grade]) -> C | M5: {=_xlfn.XLOOKUP(Table1[[#This Row],[Student ID]]&Table1[[#This Row],[Course ID]],Table9[Student ID]&Table9[Course ID],Table9[Status],"No Record")} -> present | N5: =_xlfn.XLOOKUP(Table1[[#This Row],[Student ID]],Table7[Student ID],Table7[Amount Paid],0) -> 12000
A6: Computer Science | B6: =AVERAGE(K2:K4,K8,K12) -> 88 | F6: =_xlfn.XLOOKUP(Original!B43,Table3[Student ID],Table3[Student ID]) -> 4 | G6: =_xlfn.XLOOKUP(Original!B6,Table2[Student Name],Table2[Student Name]) -> Sneha | H6: =_xlfn.XLOOKUP(Original!C43,Table3[Course ID],Table3[Course ID]) -> 4 | I6: =_xlfn.XLOOKUP(Table1[[#This Row],[Course ID]],Table4[Course ID],Table4[[Course Name ]]) -> Circuit Analysis | J6: =_xlfn.XLOOKUP(Table1[[#This Row],[Course ID]],Table4[Course ID],Table4[Department]) -> Electrical | K6: =_xlfn.XLOOKUP(Original!D43,Table3[Score],Table3[Score]) -> 82 | L6: =_xlfn.XLOOKUP(Original!E43,Table3[Grade],Table3[Grade]) -> B | M6: {=_xlfn.XLOOKUP(Table1[[#This Row],[Student ID]]&Table1[[#This Row],[Course ID]],Table9[Student ID]&Table9[Course ID],Table9[Status],"No Record")} -> present | N6: =_xlfn.XLOOKUP(Table1[[#This Row],[Student ID]],Table7[Student ID],Table7[Amount Paid],0) -> 15000
A7: Mechanical | B7: =AVERAGE(K5,K7) -> 71 | F7: =_xlfn.XLOOKUP(Original!B44,Table3[Student ID],Table3[Student ID]) -> 5 | G7: =_xlfn.XLOOKUP(Original!B7,Table2[Student Name],Table2[Student Name]) -> Vikram | H7: =_xlfn.XLOOKUP(Original!C44,Table3[Course ID],Table3[Course ID]) -> 3 | I7: =_xlfn.XLOOKUP(Table1[[#This Row],[Course ID]],Table4[Course ID],Table4[[Course Name ]]) -> Thermodynamics | J7: =_xlfn.XLOOKUP(Table1[[#This Row],[Course ID]],Table4[Course ID],Table4[Department]) -> Mechanical | K7: =_xlfn.XLOOKUP(Original!D44,Table3[Score],Table3[Score]) -> 73 | L7: =_xlfn.XLOOKUP(Original!E44,Table3[Grade],Table3[Grade]) -> B | M7: {=_xlfn.XLOOKUP(Table1[[#This Row],[Student ID]]&Table1[[#This Row],[Course ID]],Table9[Student ID]&Table9[Course ID],Table9[Status],"No Record")} -> excused | N7: =_xlfn.XLOOKUP(Table1[[#This Row],[Student ID]],Table7[Student ID],Table7[Amount Paid],0) -> 0
A8: Electrical | B8: =AVERAGE(K6,Table1[[#This Row],[Score]]) -> 88.5 | F8: =_xlfn.XLOOKUP(Original!B45,Table3[Student ID],Table3[Student ID]) -> 6 | G8: =_xlfn.XLOOKUP(Original!B8,Table2[Student Name],Table2[Student Name]) -> Priya | H8: =_xlfn.XLOOKUP(Original!C45,Table3[Course ID],Table3[Course ID]) -> 2 | I8: =_xlfn.XLOOKUP(Table1[[#This Row],[Course ID]],Table4[Course ID],Table4[[Course Name ]]) -> Machine Learning | J8: =_xlfn.XLOOKUP(Table1[[#This Row],[Course ID]],Table4[Course ID],Table4[Department]) -> Computer Science | K8: =_xlfn.XLOOKUP(Original!D45,Table3[Score],Table3[Score]) -> 95 | L8: =_xlfn.XLOOKUP(Original!E45,Table3[Grade],Table3[Grade]) -> A | M8: {=_xlfn.XLOOKUP(Table1[[#This Row],[Student ID]]&Table1[[#This Row],[Course ID]],Table9[Student ID]&Table9[Course ID],Table9[Status],"No Record")} -> No Record | N8: =_xlfn.XLOOKUP(Table1[[#This Row],[Student ID]],Table7[Student ID],Table7[Amount Paid],0) -> 0
A9: Civil | B9: =AVERAGE(K10:K11) -> 82 | F9: =_xlfn.XLOOKUP(Original!B46,Table3[Student ID],Table3[Student ID]) -> 7 | G9: =_xlfn.XLOOKUP(Original!B9,Table2[Student Name],Table2[Student Name]) -> Rohit | H9: =_xlfn.XLOOKUP(Original!C46,Table3[Course ID],Table3[Course ID]) -> 4 | I9: =_xlfn.XLOOKUP(Table1[[#This Row],[Course ID]],Table4[Course ID],Table4[[Course Name ]]) -> Circuit Analysis | J9: =_xlfn.XLOOKUP(Table1[[#This Row],[Course ID]],Table4[Course ID],Table4[Department]) -> Electrical | K9: =_xlfn.XLOOKUP(Original!D46,Table3[Score],Table3[Score]) -> 67 | L9: =_xlfn.XLOOKUP(Original!E46,Table3[Grade],Table3[Grade]) -> C | M9: {=_xlfn.XLOOKUP(Table1[[#This Row],[Student ID]]&Table1[[#This Row],[Course ID]],Table9[Student ID]&Table9[Course ID],Table9[Status],"No Record")} -> No Record | N9: =_xlfn.XLOOKUP(Table1[[#This Row],[Student ID]],Table7[Student ID],Table7[Amount Paid],0) -> 0
F10: =_xlfn.XLOOKUP(Original!B47,Table3[Student ID],Table3[Student ID]) -> 8 | G10: =_xlfn.XLOOKUP(Original!B10,Table2[Student Name],Table2[Student Name]) -> Neha | H10: =_xlfn.XLOOKUP(Original!C47,Table3[Course ID],Table3[Course ID]) -> 5 | I10: =_xlfn.XLOOKUP(Table1[[#This Row],[Course ID]],Table4[Course ID],Table4[[Course Name ]]) -> Structural Design | J10: =_xlfn.XLOOKUP(Table1[[#This Row],[Course ID]],Table4[Course ID],Table4[Department]) -> Civil | K10: =_xlfn.XLOOKUP(Original!D47,Table3[Score],Table3[Score]) -> 79 | L10: =_xlfn.XLOOKUP(Original!E47,Table3[Grade],Table3[Grade]) -> B | M10: {=_xlfn.XLOOKUP(Table1[[#This Row],[Student ID]]&Table1[[#This Row],[Course ID]],Table9[Student ID]&Table9[Course ID],Table9[Status],"No Record")} -> No Record | N10: =_xlfn.XLOOKUP(Table1[[#This Row],[Student ID]],Table7[Student ID],Table7[Amount Paid],0) -> 0
A11: Attendance Count By Status | F11: =_xlfn.XLOOKUP(Original!B48,Table3[Student ID],Table3[Student ID]) -> 9 | G11: =_xlfn.XLOOKUP(Original!B11,Table2[Student Name],Table2[Student Name]) -> Kiran | H11: =_xlfn.XLOOKUP(Original!C48,Table3[Course ID],Table3[Course ID]) -> 5 | I11: =_xlfn.XLOOKUP(Table1[[#This Row],[Course ID]],Table4[Course ID],Table4[[Course Name ]]) -> Structural Design | J11: =_xlfn.XLOOKUP(Table1[[#This Row],[Course ID]],Table4[Course ID],Table4[Department]) -> Civil | K11: =_xlfn.XLOOKUP(Original!D48,Table3[Score],Table3[Score]) -> 85 | L11: =_xlfn.XLOOKUP(Original!E48,Table3[Grade],Table3[Grade]) -> A | M11: {=_xlfn.XLOOKUP(Table1[[#This Row],[Student ID]]&Table1[[#This Row],[Course ID]],Table9[Student ID]&Table9[Course ID],Table9[Status],"No Record")} -> No Record | N11: =_xlfn.XLOOKUP(Table1[[#This Row],[Student ID]],Table7[Student ID],Table7[Amount Paid],0) -> 0
A12: Present | B12: =COUNTA(M2:M3,M5:M6) -> 4 | F12: =_xlfn.XLOOKUP(Original!B49,Table3[Student ID],Table3[Student ID]) -> 10 | G12: =_xlfn.XLOOKUP(Original!B12,Table2[Student Name],Table2[Student Name]) -> Anjali | H12: =_xlfn.XLOOKUP(Original!C49,Table3[Course ID],Table3[Course ID]) -> 6 | I12: =_xlfn.XLOOKUP(Table1[[#This Row],[Course ID]],Table4[Course ID],Table4[[Course Name ]]) -> Database Systems | J12: =_xlfn.XLOOKUP(Table1[[#This Row],[Course ID]],Table4[Course ID],Table4[Department]) -> Computer Science | K12: =_xlfn.XLOOKUP(Original!D49,Table3[Score],Table3[Score]) -> 90 | L12: =_xlfn.XLOOKUP(Original!E49,Table3[Grade],Table3[Grade]) -> A | M12: {=_xlfn.XLOOKUP(Table1[[#This Row],[Student ID]]&Table1[[#This Row],[Course ID]],Table9[Student ID]&Table9[Course ID],Table9[Status],"No Record")} -> No Record | N12: =_xlfn.XLOOKUP(Table1[[#This Row],[Student ID]],Table7[Student ID],Table7[Amount Paid],0) -> 0
A13: Absent | B13: =COUNTA(M4) -> 1
A14: Excused | B14: =COUNTA(M7) -> 1
A16: Total payment Amont | B16: =SUM(N2:N6) -> 72000

Sheet Dashboard
K1: Student Grade Management Dashboard

Sheet Average Score By Department
A1: Row Labels | B1: Average of Score
A2: Civil | B2: 82
A3: Computer Science | B3: 88
A4: Electrical | B4: 74.5
A5: Mechanical | B5: 71
A6: Grand Total | B6: 81.363636

Sheet Students By Department
A1: Row Labels | B1: Count of Student ID
A2: Civil | B2: 2
A3: Computer Science | B3: 5
A4: Electrical | B4: 2
A5: Mechanical | B5: 2
A6: Grand Total | B6: 11

Sheet Top Scorer By Course
A1: Row Labels | B1: Max of Score
A2: Circuit Analysis | B2: 82
A3: Data Structures | B3: 88
A4: Database Systems | B4: 90
A5: Machine Learning | B5: 95
A6: Structural Design | B6: 85
A7: Thermodynamics | B7: 73
A8: Grand Total | B8: 95

Sheet Attendance vs Score
A1: Row Labels | B1: Average of Score
A2: absent | B2: 76
A3: excused | B3: 73
A4: No Record | B4: 83.2
A5: present | B5: 82.5
A6: Grand Total | B6: 81.363636

Sheet Payment Analysis
A1: Row Labels | B1: Sum of Amount Paid
A2: Anjali | B2: 0
A3: Arjun | B3: 30000
A4: Kiran | B4: 0
A5: Meera | B5: 15000
A6: Neha | B6: 0
A7: Priya | B7: 0
A8: Ravi | B8: 12000
A9: Rohit | B9: 0
A10: Sneha | B10: 15000
A11: Vikram | B11: 0
A12: Grand Total | B12: 72000
